	from blog.models import Post
>>> Post.objects.all()
[<Post: first test post>, <Post: second test post>, <Post: third test post>]
>>> from django.utils import timezone
>>> p = Post(author = "Taka", title = "First shell test", text = "still test test test....", created_date=timezone.now(), published_date = timezone.now()+datetime.timedelta(days=1))
Traceback (most recent call last):
  File "/Users/takahirodoi/djangogirls/myvenv/lib/python3.5/site-packages/django/core/management/commands/shell.py", line 69, in handle
    self.run_shell(shell=options['interface'])
  File "/Users/takahirodoi/djangogirls/myvenv/lib/python3.5/site-packages/django/core/management/commands/shell.py", line 61, in run_shell
    raise ImportError
ImportError

During handling of the above exception, another exception occurred:

Traceback (most recent call last):
  File "<console>", line 1, in <module>
NameError: name 'datetime' is not defined
>>> import datetime
>>> p = Post(author = "Taka", title = "First shell test", text = "still test test test....", created_date=timezone.now(), published_date = timezone.now()+datetime.timedelta(days=1))
Traceback (most recent call last):
  File "/Users/takahirodoi/djangogirls/myvenv/lib/python3.5/site-packages/django/core/management/commands/shell.py", line 69, in handle
    self.run_shell(shell=options['interface'])
  File "/Users/takahirodoi/djangogirls/myvenv/lib/python3.5/site-packages/django/core/management/commands/shell.py", line 61, in run_shell
    raise ImportError
ImportError

During handling of the above exception, another exception occurred:

Traceback (most recent call last):
  File "<console>", line 1, in <module>
  File "/Users/takahirodoi/djangogirls/myvenv/lib/python3.5/site-packages/django/db/models/base.py", line 439, in __init__
    setattr(self, field.name, rel_obj)
  File "/Users/takahirodoi/djangogirls/myvenv/lib/python3.5/site-packages/django/db/models/fields/related_descriptors.py", line 207, in __set__
    self.field.remote_field.model._meta.object_name,
ValueError: Cannot assign "'Taka'": "Post.author" must be a "User" instance.
>>> p = Post(author = "Taka", title = "First shell test", text = "still test test test....", created_date=timezone.now(), published_date = timezone.now()+datetime.timedelta(days=1))
Traceback (most recent call last):
  File "/Users/takahirodoi/djangogirls/myvenv/lib/python3.5/site-packages/django/core/management/commands/shell.py", line 69, in handle
    self.run_shell(shell=options['interface'])
  File "/Users/takahirodoi/djangogirls/myvenv/lib/python3.5/site-packages/django/core/management/commands/shell.py", line 61, in run_shell
    raise ImportError
ImportError

During handling of the above exception, another exception occurred:

Traceback (most recent call last):
  File "<console>", line 1, in <module>
  File "/Users/takahirodoi/djangogirls/myvenv/lib/python3.5/site-packages/django/db/models/base.py", line 439, in __init__
    setattr(self, field.name, rel_obj)
  File "/Users/takahirodoi/djangogirls/myvenv/lib/python3.5/site-packages/django/db/models/fields/related_descriptors.py", line 207, in __set__
    self.field.remote_field.model._meta.object_name,
ValueError: Cannot assign "'Taka'": "Post.author" must be a "User" instance.

